Workbook

Sheet Sheet2
B2: 기준월 | C2: 8월
B3: 500000
B4: 제품유형 | D4: 플랫폼 | E4: 차/대 | F4: 계정과목 | G4: 금액 | H4: 공금가액 | I4: 공급대가 | K4: 플랫폼 | L4: 차/대 | M4: 계정과목 | N4: 금액 | O4: 공금가액 | P4: 공급대가 | R4: 플랫폼 | S4: 차/대 | T4: 계정과목 | U4: 금액 | V4: 공금가액 | W4: 공급대가 | Y4: 플랫폼 | Z4: 아마란스_잔액
D5: 네이버 | E5: 차변 | F5: 외상매출금 | G5: =SUM(I13:I16) -> 24166000 | K5: 쿠팡 | L5: 차변 | M5: 외상매출금 | N5: =SUM(P13:P16) -> 6600000 | R5: 카페24 | S5: 차변 | T5: 외상매출금 | U5: =SUM(W13:W16) -> 485000 | Z5: 선수금 | AA5: 수수료 | AB5: 외상매출금
B6: 부가제품 | E6: 차변 | F6: 오므론 | G6: =I6/1.1 -> -403635.45 | I6: =-SUMIFS('[1]통합 판매내역'!H:H,'[1]통합 판매내역'!E:E,[1]회계!B6,'[1]통합 판매내역'!A:A,[1]회계!D5,'[1]통합 판매내역'!C:C,$C$2)-SUMIFS('[1]통합 판매내역'!I:I,'[1]통합 판매내역'!E:E,[1]회계!B6,'[1]통합 판매내역'!A:A,[1]회계!D5,'[1]통합 판매내역'!C:C,$C$2)-SUMIFS('[1]통합 판매내역'!J:J,'[1]통합 판매내역'!E:E,[1]회계!B6,'[1]통합 판매내역'!A:A,[1]회계!D5,'[1]통합 판매내역'!C:C,$C$2)-SUMIFS('[1]통합 판매내역'!K:K,'[1]통합 판매내역'!E:E,[1]회계!B6,'[1]통합 판매내역'!A:A,[1]회계!D5,'[1]통합 판매내역'!C:C,$C$2) -> -443999 | L6: 차변 | M6: 오므론 | N6: =P6/1.1 -> 0 | P6: =-SUMIFS('[1]통합 판매내역'!H:H,'[1]통합 판매내역'!E:E,[1]회계!B6,'[1]통합 판매내역'!A:A,K5,'[1]통합 판매내역'!C:C,$C$2)-SUMIFS('[1]통합 판매내역'!I:I,'[1]통합 판매내역'!E:E,[1]회계!B6,'[1]통합 판매내역'!A:A,K5,'[1]통합 판매내역'!C:C,$C$2)-SUMIFS('[1]통합 판매내역'!J:J,'[1]통합 판매내역'!E:E,[1]회계!B6,'[1]통합 판매내역'!A:A,K5,'[1]통합 판매내역'!C:C,$C$2)-SUMIFS('[1]통합 판매내역'!K:K,'[1]통합 판매내역'!E:E,[1]회계!B6,'[1]통합 판매내역'!A:A,K5,'[1]통합 판매내역'!C:C,$C$2) -> 0 | S6: 차변 | T6: 오므론 | U6: =W6/1.1 -> 67272.727 | W6: =-SUMIFS('[1]통합 판매내역'!H:H,'[1]통합 판매내역'!E:E,[1]회계!B21,'[1]통합 판매내역'!A:A,[1]회계!R5,'[1]통합 판매내역'!C:C,$C$2)-SUMIFS('[1]통합 판매내역'!I:I,'[1]통합 판매내역'!E:E,[1]회계!B21,'[1]통합 판매내역'!A:A,[1]회계!R5,'[1]통합 판매내역'!C:C,$C$2)-SUMIFS('[1]통합 판매내역'!J:J,'[1]통합 판매내역'!E:E,[1]회계!B21,'[1]통합 판매내역'!A:A,[1]회계!R5,'[1]통합 판매내역'!C:C,$C$2)-SUMIFS('[1]통합 판매내역'!K:K,'[1]통합 판매내역'!E:E,[1]회계!B21,'[1]통합 판매내역'!A:A,[1]회계!R5,'[1]통합 판매내역'!C:C,$C$2) -> 74000 | Y6: 네이버 | Z6: 9111888 | AA6: 3177367
B7: 배송비 | E7: 차변 | F7: 배송비 | G7: =I7/1.1 -> -65454.545 | I7: =-SUMIFS('[1]통합 판매내역'!H:H,'[1]통합 판매내역'!E:E,[1]회계!B7,'[1]통합 판매내역'!A:A,D5,'[1]통합 판매내역'!C:C,$C$2)-SUMIFS('[1]통합 판매내역'!I:I,'[1]통합 판매내역'!E:E,[1]회계!B7,'[1]통합 판매내역'!A:A,D5,'[1]통합 판매내역'!C:C,$C$2)-SUMIFS('[1]통합 판매내역'!J:J,'[1]통합 판매내역'!E:E,[1]회계!B7,'[1]통합 판매내역'!A:A,D5,'[1]통합 판매내역'!C:C,$C$2)-SUMIFS('[1]통합 판매내역'!K:K,'[1]통합 판매내역'!E:E,[1]회계!B7,'[1]통합 판매내역'!A:A,D5,'[1]통합 판매내역'!C:C,$C$2) -> -72000 | L7: 차변 | M7: 배송비 | N7: =P7/1.1 -> 0 | P7: =-SUMIFS('[1]통합 판매내역'!H:H,'[1]통합 판매내역'!E:E,[1]회계!B7,'[1]통합 판매내역'!A:A,K5,'[1]통합 판매내역'!C:C,$C$2)-SUMIFS('[1]통합 판매내역'!I:I,'[1]통합 판매내역'!E:E,[1]회계!B7,'[1]통합 판매내역'!A:A,K5,'[1]통합 판매내역'!C:C,$C$2)-SUMIFS('[1]통합 판매내역'!J:J,'[1]통합 판매내역'!E:E,[1]회계!B7,'[1]통합 판매내역'!A:A,K5,'[1]통합 판매내역'!C:C,$C$2)-SUMIFS('[1]통합 판매내역'!K:K,'[1]통합 판매내역'!E:E,[1]회계!B7,'[1]통합 판매내역'!A:A,K5,'[1]통합 판매내역'!C:C,$C$2) -> 0 | S7: 차변 | T7: 배송비 | U7: =W7/1.1 -> -8181.8182 | W7: =-SUMIFS('[1]통합 판매내역'!H:H,'[1]통합 판매내역'!E:E,[1]회계!B22,'[1]통합 판매내역'!A:A,R5,'[1]통합 판매내역'!C:C,$C$2)-SUMIFS('[1]통합 판매내역'!I:I,'[1]통합 판매내역'!E:E,[1]회계!B22,'[1]통합 판매내역'!A:A,R5,'[1]통합 판매내역'!C:C,$C$2)-SUMIFS('[1]통합 판매내역'!J:J,'[1]통합 판매내역'!E:E,[1]회계!B22,'[1]통합 판매내역'!A:A,R5,'[1]통합 판매내역'!C:C,$C$2)-SUMIFS('[1]통합 판매내역'!K:K,'[1]통합 판매내역'!E:E,[1]회계!B22,'[1]통합 판매내역'!A:A,R5,'[1]통합 판매내역'!C:C,$C$2) -> -9000 | Y7: 쿠팡 | Z7: 6966567 | AA7: 3641434 | AB7: 10758001
B8: 제품확정 | E8: 차변 | F8: 선수금 | G8: =500000*SUMIFS('[1]통합 판매내역'!G:G,'[1]통합 판매내역'!E:E,[1]회계!B8,'[1]통합 판매내역'!A:A,[1]회계!D5,'[1]통합 판매내역'!C:C,$C$2) -> 0 | L8: 차변 | M8: 선수금 | N8: =500000*SUMIFS('[1]통합 판매내역'!G:G,'[1]통합 판매내역'!E:E,[1]회계!B8,'[1]통합 판매내역'!A:A,K5,'[1]통합 판매내역'!C:C,$C$2) -> 500000 | S8: 차변 | T8: 선수금 | U8: =500000*SUMIFS('[1]통합 판매내역'!G:G,'[1]통합 판매내역'!E:E,[1]회계!B23,'[1]통합 판매내역'!A:A,[1]회계!R5,'[1]통합 판매내역'!C:C,$C$2) -> 500000 | X8: (KG/네오) | Y8: 카페24 | AA8: 231804
B9: 사이즈미정 | E9: 차변 | F9: 선수금 | G9: =I9/1.1 -> -1500000 | I9: =-SUMIFS('[1]통합 판매내역'!H:H,'[1]통합 판매내역'!E:E,B9,'[1]통합 판매내역'!A:A,D5,'[1]통합 판매내역'!C:C,$C$2)-SUMIFS('[1]통합 판매내역'!I:I,'[1]통합 판매내역'!E:E,B9,'[1]통합 판매내역'!A:A,D5,'[1]통합 판매내역'!C:C,$C$2)-SUMIFS('[1]통합 판매내역'!J:J,'[1]통합 판매내역'!E:E,B9,'[1]통합 판매내역'!A:A,D5,'[1]통합 판매내역'!C:C,$C$2)-SUMIFS('[1]통합 판매내역'!K:K,'[1]통합 판매내역'!E:E,B9,'[1]통합 판매내역'!A:A,D5,'[1]통합 판매내역'!C:C,$C$2) -> -1650000 | L9: 차변 | M9: 선수금 | N9: =P9/1.1 -> 0 | P9: =-SUMIFS('[1]통합 판매내역'!H:H,'[1]통합 판매내역'!E:E,B9,'[1]통합 판매내역'!A:A,K5,'[1]통합 판매내역'!C:C,$C$2)-SUMIFS('[1]통합 판매내역'!I:I,'[1]통합 판매내역'!E:E,B9,'[1]통합 판매내역'!A:A,K5,'[1]통합 판매내역'!C:C,$C$2)-SUMIFS('[1]통합 판매내역'!J:J,'[1]통합 판매내역'!E:E,B9,'[1]통합 판매내역'!A:A,K5,'[1]통합 판매내역'!C:C,$C$2)-SUMIFS('[1]통합 판매내역'!K:K,'[1]통합 판매내역'!E:E,B9,'[1]통합 판매내역'!A:A,K5,'[1]통합 판매내역'!C:C,$C$2) -> 0 | S9: 차변 | T9: 선수금 | U9: =W9/1.1 -> 500000 | W9: =-SUMIFS('[1]통합 판매내역'!H:H,'[1]통합 판매내역'!E:E,B9,'[1]통합 판매내역'!A:A,R5,'[1]통합 판매내역'!C:C,$C$2)-SUMIFS('[1]통합 판매내역'!I:I,'[1]통합 판매내역'!E:E,B9,'[1]통합 판매내역'!A:A,R5,'[1]통합 판매내역'!C:C,$C$2)-SUMIFS('[1]통합 판매내역'!J:J,'[1]통합 판매내역'!E:E,B9,'[1]통합 판매내역'!A:A,R5,'[1]통합 판매내역'!C:C,$C$2)-SUMIFS('[1]통합 판매내역'!K:K,'[1]통합 판매내역'!E:E,B9,'[1]통합 판매내역'!A:A,R5,'[1]통합 판매내역'!C:C,$C$2) -> 550000 | Y9: 11번가
B10: 제품 | E10: 대변 | F10: 제품매출 | G10: =SUMIFS('[1]통합 판매내역'!G:G,'[1]통합 판매내역'!E:E,[1]회계!B10,'[1]통합 판매내역'!A:A,[1]회계!D5,'[1]통합 판매내역'!C:C,$C$2)*B3 -> 20500000 | I10: =SUMIFS('[1]통합 판매내역'!G:G,'[1]통합 판매내역'!E:E,[1]회계!B10,'[1]통합 판매내역'!A:A,[1]회계!D5,'[1]통합 판매내역'!C:C,$C$2) -> 41 | L10: 대변 | M10: 제품매출 | N10: =SUMIFS('[1]통합 판매내역'!G:G,'[1]통합 판매내역'!E:E,[1]회계!B10,'[1]통합 판매내역'!A:A,K5,'[1]통합 판매내역'!C:C,$C$2)*B3 -> 6000000 | P10: =SUMIFS('[1]통합 판매내역'!G:G,'[1]통합 판매내역'!E:E,[1]회계!B10,'[1]통합 판매내역'!A:A,K5,'[1]통합 판매내역'!C:C,$C$2) -> 12 | S10: 대변 | T10: 제품매출 | U10: =SUMIFS('[1]통합 판매내역'!G:G,'[1]통합 판매내역'!E:E,[1]회계!B10,'[1]통합 판매내역'!A:A,R5,'[1]통합 판매내역'!C:C,$C$2)*B3 -> 1000000 | W10: =SUMIFS('[1]통합 판매내역'!G:G,'[1]통합 판매내역'!E:E,[1]회계!B10,'[1]통합 판매내역'!A:A,R5,'[1]통합 판매내역'!C:C,$C$2) -> 2 | Y10: 지마켓 | Z10: 500500
B11: 제품확정 | E11: 대변 | F11: 제품매출 | G11: =SUMIFS('[1]통합 판매내역'!G:G,'[1]통합 판매내역'!E:E,B11,'[1]통합 판매내역'!A:A,[1]회계!D5,'[1]통합 판매내역'!C:C,$C$2)*B3 -> 0 | I11: =SUMIFS('[1]통합 판매내역'!G:G,'[1]통합 판매내역'!E:E,B11,'[1]통합 판매내역'!A:A,[1]회계!D5,'[1]통합 판매내역'!C:C,$C$2) -> 0 | L11: 대변 | M11: 제품매출 | N11: =SUMIFS('[1]통합 판매내역'!G:G,'[1]통합 판매내역'!E:E,B11,'[1]통합 판매내역'!A:A,K5,'[1]통합 판매내역'!C:C,$C$2)*B3 -> 500000 | P11: =SUMIFS('[1]통합 판매내역'!G:G,'[1]통합 판매내역'!E:E,B11,'[1]통합 판매내역'!A:A,K5,'[1]통합 판매내역'!C:C,$C$2) -> 1 | S11: 대변 | T11: 제품매출 | U11: =500000*SUMIFS('[1]통합 판매내역'!G:G,'[1]통합 판매내역'!E:E,B11,'[1]통합 판매내역'!A:A,[1]회계!R5,'[1]통합 판매내역'!C:C,$C$2) -> 500000 | W11: =SUMIFS('[1]통합 판매내역'!G:G,'[1]통합 판매내역'!E:E,B11,'[1]통합 판매내역'!A:A,[1]회계!R5,'[1]통합 판매내역'!C:C,$C$2) -> 1 | Y11: SSG
B12: 제품취소 | E12: 대변 | F12: 제품매출(취소) | G12: =SUMIFS('[1]통합 판매내역'!G:G,'[1]통합 판매내역'!E:E,[1]회계!B12,'[1]통합 판매내역'!A:A,[1]회계!D5,'[1]통합 판매내역'!C:C,$C$2)*B3 -> -500000 | I12: =SUMIFS('[1]통합 판매내역'!G:G,'[1]통합 판매내역'!E:E,[1]회계!B12,'[1]통합 판매내역'!A:A,[1]회계!D5,'[1]통합 판매내역'!C:C,$C$2) -> -1 | L12: 대변 | M12: 제품매출(취소) | N12: =SUMIFS('[1]통합 판매내역'!G:G,'[1]통합 판매내역'!E:E,[1]회계!B12,'[1]통합 판매내역'!A:A,K5,'[1]통합 판매내역'!C:C,$C$2)*B3 -> 0 | P12: =SUMIFS('[1]통합 판매내역'!G:G,'[1]통합 판매내역'!E:E,[1]회계!B12,'[1]통합 판매내역'!A:A,K5,'[1]통합 판매내역'!C:C,$C$2) -> 0 | S12: 대변 | T12: 제품매출(취소) | U12: =SUMIFS('[1]통합 판매내역'!G:G,'[1]통합 판매내역'!E:E,[1]회계!B12,'[1]통합 판매내역'!A:A,R5,'[1]통합 판매내역'!C:C,$C$2)*B3 -> 0 | W12: =SUMIFS('[1]통합 판매내역'!G:G,'[1]통합 판매내역'!E:E,[1]회계!B12,'[1]통합 판매내역'!A:A,R5,'[1]통합 판매내역'!C:C,$C$2) -> 0 | X12: (SK M&N) | Y12: 베네피아
B13: 신용카드 | E13: 대변 | F13: 부가세예수금 | G13: =H13*10% -> 1721486.5 | H13: =I13/1.1 -> 17214865 | I13: =SUMIFS('[1]통합 판매내역'!H:H,'[1]통합 판매내역'!A:A,[1]회계!D5,'[1]통합 판매내역'!C:C,$C$2) -> 18936351 | L13: 대변 | M13: 부가세예수금 | N13: =O13*10% -> 548000 | O13: =P13/1.1 -> 5480000 | P13: =SUMIFS('[1]통합 판매내역'!H:H,'[1]통합 판매내역'!A:A,K5,'[1]통합 판매내역'!C:C,$C$2) -> 6028000 | S13: 대변 | T13: 부가세예수금 | U13: =V13*10% -> -5909.0909 | V13: =W13/1.1 -> -59090.909 | W13: =SUMIFS('[1]통합 판매내역'!H:H,'[1]통합 판매내역'!A:A,[1]회계!R5,'[1]통합 판매내역'!C:C,$C$2) -> -65000 | Y13: 옥션 | AB13: 540000
B14: 현금영수증 | E14: 대변 | F14: 부가세예수금 | G14: =H14*10% -> 404890.45 | H14: =I14/1.1 -> 4048904.5 | I14: =SUMIFS('[1]통합 판매내역'!I:I,'[1]통합 판매내역'!A:A,[1]회계!D5,'[1]통합 판매내역'!C:C,$C$2) -> 4453795 | L14: 대변 | M14: 부가세예수금 | N14: =O14*10% -> 50000 | O14: =P14/1.1 -> 500000 | P14: =SUMIFS('[1]통합 판매내역'!I:I,'[1]통합 판매내역'!A:A,K5,'[1]통합 판매내역'!C:C,$C$2) -> 550000 | S14: 대변 | T14: 부가세예수금 | U14: =V14*10% -> 50000 | V14: =W14/1.1 -> 500000 | W14: =SUMIFS('[1]통합 판매내역'!I:I,'[1]통합 판매내역'!A:A,[1]회계!R5,'[1]통합 판매내역'!C:C,$C$2) -> 550000
B15: 기타 | E15: 대변 | F15: 부가세예수금 | G15: =H15*10% -> 20532.182 | H15: =I15/1.1 -> 205321.82 | I15: =SUMIFS('[1]통합 판매내역'!K:K,'[1]통합 판매내역'!A:A,[1]회계!D5,'[1]통합 판매내역'!C:C,$C$2) -> 225854 | L15: 대변 | M15: 부가세예수금 | N15: =O15*10% -> 2000 | O15: =P15/1.1 -> 20000 | P15: =SUMIFS('[1]통합 판매내역'!K:K,'[1]통합 판매내역'!A:A,K5,'[1]통합 판매내역'!C:C,$C$2) -> 22000 | S15: 대변 | T15: 부가세예수금 | U15: =V15*10% -> 0 | V15: =W15/1.1 -> 0 | W15: =SUMIFS('[1]통합 판매내역'!K:K,'[1]통합 판매내역'!A:A,[1]회계!R5,'[1]통합 판매내역'!C:C,$C$2) -> 0
B16: 세금계산서 | E16: 대변 | F16: 부가세예수금 | G16: =H16*10% -> 50000 | H16: =I16/1.1 -> 500000 | I16: =SUMIFS('[1]통합 판매내역'!J:J,'[1]통합 판매내역'!A:A,[1]회계!D5,'[1]통합 판매내역'!C:C,$C$2) -> 550000 | L16: 대변 | M16: 부가세예수금 | N16: =O16*10% -> 0 | O16: =P16/1.1 -> 0 | P16: =SUMIFS('[1]통합 판매내역'!J:J,'[1]통합 판매내역'!A:A,K5,'[1]통합 판매내역'!C:C,$C$2) -> 0 | S16: 대변 | T16: 부가세예수금 | U16: =V16*10% -> 0 | V16: =W16/1.1 -> 0 | W16: =SUMIFS('[1]통합 판매내역'!J:J,'[1]통합 판매내역'!A:A,[1]회계!R5,'[1]통합 판매내역'!C:C,$C$2) -> 0
E17: 차변 | F17: 수수료(차액) | G17: =SUMIFS(G5:G16,E5:E16,"대변")-SUMIFS(G5:G16,E5:E16,"차변") -> -0.90909091 | L17: 차변 | M17: 수수료(차액) | N17: =SUMIFS(N5:N16,L5:L16,"대변")-SUMIFS(N5:N16,L5:L16,"차변") -> 0 | S17: 차변 | T17: 수수료(차액) | U17: =SUMIFS(U5:U16,S5:S16,"대변")-SUMIFS(U5:U16,S5:S16,"차변") -> 0 | Z17: =SUM(Z6:Z16) -> 16578955 | AA17: =SUM(AA6:AA16) -> 7050605 | AB17: =SUM(AB6:AB16) -> 11298001
B18: 500000
B19: 제품유형 | D19: 플랫폼 | E19: 차/대 | F19: 계정과목 | G19: 금액 | H19: 공금가액 | I19: 공급대가 | K19: 플랫폼 | L19: 차/대 | M19: 계정과목 | N19: 금액 | O19: 공금가액 | P19: 공급대가 | R19: 플랫폼 | S19: 차/대 | T19: 계정과목 | U19: 금액 | V19: 공금가액 | W19: 공급대가
D20: 11번가 | E20: 차변 | F20: 외상매출금 | G20: =SUM(I28:I31) -> 0 | K20: SSG | L20: 차변 | M20: 외상매출금 | N20: =SUM(P28:P31) -> 1733000 | R20: 지마켓 | S20: 차변 | T20: 외상매출금 | U20: =SUM(W28:W31) -> 0
B21: 부가제품 | E21: 차변 | F21: 오므론 | G21: =I21/1.1 -> 0 | I21: =-SUMIFS('[1]통합 판매내역'!H:H,'[1]통합 판매내역'!E:E,[1]회계!B21,'[1]통합 판매내역'!A:A,D20,'[1]통합 판매내역'!C:C,$C$2)-SUMIFS('[1]통합 판매내역'!I:I,'[1]통합 판매내역'!E:E,[1]회계!B21,'[1]통합 판매내역'!A:A,D20,'[1]통합 판매내역'!C:C,$C$2)-SUMIFS('[1]통합 판매내역'!J:J,'[1]통합 판매내역'!E:E,[1]회계!B21,'[1]통합 판매내역'!A:A,D20,'[1]통합 판매내역'!C:C,$C$2)-SUMIFS('[1]통합 판매내역'!K:K,'[1]통합 판매내역'!E:E,[1]회계!B21,'[1]통합 판매내역'!A:A,D20,'[1]통합 판매내역'!C:C,$C$2) -> 0 | L21: 차변 | M21: 오므론 | N21: =P21/1.1 -> -67272.727 | P21: =-SUMIFS('[1]통합 판매내역'!H:H,'[1]통합 판매내역'!E:E,[1]회계!B36,'[1]통합 판매내역'!A:A,[1]회계!K20,'[1]통합 판매내역'!C:C,$C$2)-SUMIFS('[1]통합 판매내역'!I:I,'[1]통합 판매내역'!E:E,[1]회계!B36,'[1]통합 판매내역'!A:A,[1]회계!K20,'[1]통합 판매내역'!C:C,$C$2)-SUMIFS('[1]통합 판매내역'!J:J,'[1]통합 판매내역'!E:E,[1]회계!B36,'[1]통합 판매내역'!A:A,[1]회계!K20,'[1]통합 판매내역'!C:C,$C$2)-SUMIFS('[1]통합 판매내역'!K:K,'[1]통합 판매내역'!E:E,[1]회계!B36,'[1]통합 판매내역'!A:A,[1]회계!K20,'[1]통합 판매내역'!C:C,$C$2) -> -74000 | S21: 차변 | T21: 오므론 | U21: =W21/1.1 -> 0 | W21: =-SUMIFS('[1]통합 판매내역'!H:H,'[1]통합 판매내역'!E:E,[1]회계!B36,'[1]통합 판매내역'!A:A,R20,'[1]통합 판매내역'!C:C,$C$2)-SUMIFS('[1]통합 판매내역'!I:I,'[1]통합 판매내역'!E:E,[1]회계!B36,'[1]통합 판매내역'!A:A,R20,'[1]통합 판매내역'!C:C,$C$2)-SUMIFS('[1]통합 판매내역'!J:J,'[1]통합 판매내역'!E:E,[1]회계!B36,'[1]통합 판매내역'!A:A,R20,'[1]통합 판매내역'!C:C,$C$2)-SUMIFS('[1]통합 판매내역'!K:K,'[1]통합 판매내역'!E:E,[1]회계!B36,'[1]통합 판매내역'!A:A,R20,'[1]통합 판매내역'!C:C,$C$2) -> 0
B22: 배송비 | E22: 차변 | F22: 배송비 | G22: =I22/1.1 -> 0 | I22: =-SUMIFS('[1]통합 판매내역'!H:H,'[1]통합 판매내역'!E:E,[1]회계!B22,'[1]통합 판매내역'!A:A,D20,'[1]통합 판매내역'!C:C,$C$2)-SUMIFS('[1]통합 판매내역'!I:I,'[1]통합 판매내역'!E:E,[1]회계!B22,'[1]통합 판매내역'!A:A,D20,'[1]통합 판매내역'!C:C,$C$2)-SUMIFS('[1]통합 판매내역'!J:J,'[1]통합 판매내역'!E:E,[1]회계!B22,'[1]통합 판매내역'!A:A,D20,'[1]통합 판매내역'!C:C,$C$2)-SUMIFS('[1]통합 판매내역'!K:K,'[1]통합 판매내역'!E:E,[1]회계!B22,'[1]통합 판매내역'!A:A,D20,'[1]통합 판매내역'!C:C,$C$2) -> 0 | L22: 차변 | M22: 배송비 | N22: =P22/1.1 -> -8181.8182 | P22: =-SUMIFS('[1]통합 판매내역'!H:H,'[1]통합 판매내역'!E:E,[1]회계!B37,'[1]통합 판매내역'!A:A,K20,'[1]통합 판매내역'!C:C,$C$2)-SUMIFS('[1]통합 판매내역'!I:I,'[1]통합 판매내역'!E:E,[1]회계!B37,'[1]통합 판매내역'!A:A,K20,'[1]통합 판매내역'!C:C,$C$2)-SUMIFS('[1]통합 판매내역'!J:J,'[1]통합 판매내역'!E:E,[1]회계!B37,'[1]통합 판매내역'!A:A,K20,'[1]통합 판매내역'!C:C,$C$2)-SUMIFS('[1]통합 판매내역'!K:K,'[1]통합 판매내역'!E:E,[1]회계!B37,'[1]통합 판매내역'!A:A,K20,'[1]통합 판매내역'!C:C,$C$2) -> -9000 | S22: 차변 | T22: 배송비 | U22: =W22/1.1 -> 0 | W22: =-SUMIFS('[1]통합 판매내역'!H:H,'[1]통합 판매내역'!E:E,[1]회계!B37,'[1]통합 판매내역'!A:A,R20,'[1]통합 판매내역'!C:C,$C$2)-SUMIFS('[1]통합 판매내역'!I:I,'[1]통합 판매내역'!E:E,[1]회계!B37,'[1]통합 판매내역'!A:A,R20,'[1]통합 판매내역'!C:C,$C$2)-SUMIFS('[1]통합 판매내역'!J:J,'[1]통합 판매내역'!E:E,[1]회계!B37,'[1]통합 판매내역'!A:A,R20,'[1]통합 판매내역'!C:C,$C$2)-SUMIFS('[1]통합 판매내역'!K:K,'[1]통합 판매내역'!E:E,[1]회계!B37,'[1]통합 판매내역'!A:A,R20,'[1]통합 판매내역'!C:C,$C$2) -> 0
B23: 제품확정 | E23: 차변 | F23: 선수금 | G23: =500000*SUMIFS('[1]통합 판매내역'!G:G,'[1]통합 판매내역'!E:E,[1]회계!B38,'[1]통합 판매내역'!A:A,D20,'[1]통합 판매내역'!C:C,$C$2) -> 0 | L23: 차변 | M23: 선수금 | N23: =500000*SUMIFS('[1]통합 판매내역'!G:G,'[1]통합 판매내역'!E:E,[1]회계!B38,'[1]통합 판매내역'!A:A,[1]회계!K20,'[1]통합 판매내역'!C:C,$C$2) -> 0 | S23: 차변 | T23: 선수금 | U23: =500000*SUMIFS('[1]통합 판매내역'!G:G,'[1]통합 판매내역'!E:E,[1]회계!B38,'[1]통합 판매내역'!A:A,R20,'[1]통합 판매내역'!C:C,$C$2) -> 0
B24: 사이즈미정 | E24: 차변 | F24: 선수금 | G24: =I24/1.1 -> 0 | I24: =-SUMIFS('[1]통합 판매내역'!H:H,'[1]통합 판매내역'!E:E,B24,'[1]통합 판매내역'!A:A,D20,'[1]통합 판매내역'!C:C,$C$2)-SUMIFS('[1]통합 판매내역'!I:I,'[1]통합 판매내역'!E:E,B24,'[1]통합 판매내역'!A:A,D20,'[1]통합 판매내역'!C:C,$C$2)-SUMIFS('[1]통합 판매내역'!J:J,'[1]통합 판매내역'!E:E,B24,'[1]통합 판매내역'!A:A,D20,'[1]통합 판매내역'!C:C,$C$2)-SUMIFS('[1]통합 판매내역'!K:K,'[1]통합 판매내역'!E:E,B24,'[1]통합 판매내역'!A:A,D20,'[1]통합 판매내역'!C:C,$C$2) -> 0 | L24: 차변 | M24: 선수금 | N24: =P24/1.1 -> -500000 | P24: =-SUMIFS('[1]통합 판매내역'!H:H,'[1]통합 판매내역'!E:E,B24,'[1]통합 판매내역'!A:A,K20,'[1]통합 판매내역'!C:C,$C$2)-SUMIFS('[1]통합 판매내역'!I:I,'[1]통합 판매내역'!E:E,B24,'[1]통합 판매내역'!A:A,K20,'[1]통합 판매내역'!C:C,$C$2)-SUMIFS('[1]통합 판매내역'!J:J,'[1]통합 판매내역'!E:E,B24,'[1]통합 판매내역'!A:A,K20,'[1]통합 판매내역'!C:C,$C$2)-SUMIFS('[1]통합 판매내역'!K:K,'[1]통합 판매내역'!E:E,B24,'[1]통합 판매내역'!A:A,K20,'[1]통합 판매내역'!C:C,$C$2) -> -550000 | S24: 차변 | T24: 선수금 | U24: =W24/1.1 -> 0 | W24: =-SUMIFS('[1]통합 판매내역'!H:H,'[1]통합 판매내역'!E:E,B24,'[1]통합 판매내역'!A:A,R20,'[1]통합 판매내역'!C:C,$C$2)-SUMIFS('[1]통합 판매내역'!I:I,'[1]통합 판매내역'!E:E,B24,'[1]통합 판매내역'!A:A,R20,'[1]통합 판매내역'!C:C,$C$2)-SUMIFS('[1]통합 판매내역'!J:J,'[1]통합 판매내역'!E:E,B24,'[1]통합 판매내역'!A:A,R20,'[1]통합 판매내역'!C:C,$C$2)-SUMIFS('[1]통합 판매내역'!K:K,'[1]통합 판매내역'!E:E,B24,'[1]통합 판매내역'!A:A,R20,'[1]통합 판매내역'!C:C,$C$2) -> 0
B25: 제품 | E25: 대변 | F25: 제품매출 | G25: =SUMIFS('[1]통합 판매내역'!G:G,'[1]통합 판매내역'!E:E,[1]회계!B10,'[1]통합 판매내역'!A:A,D20,'[1]통합 판매내역'!C:C,$C$2)*B3 -> 0 | I25: =SUMIFS('[1]통합 판매내역'!G:G,'[1]통합 판매내역'!E:E,[1]회계!B10,'[1]통합 판매내역'!A:A,D20,'[1]통합 판매내역'!C:C,$C$2) -> 0 | L25: 대변 | M25: 제품매출 | N25: =SUMIFS('[1]통합 판매내역'!G:G,'[1]통합 판매내역'!E:E,[1]회계!B10,'[1]통합 판매내역'!A:A,K20,'[1]통합 판매내역'!C:C,$C$2)*B3 -> 1000000 | P25: =SUMIFS('[1]통합 판매내역'!G:G,'[1]통합 판매내역'!E:E,[1]회계!B10,'[1]통합 판매내역'!A:A,K20,'[1]통합 판매내역'!C:C,$C$2) -> 2 | S25: 대변 | T25: 제품매출 | U25: =SUMIFS('[1]통합 판매내역'!G:G,'[1]통합 판매내역'!E:E,[1]회계!B10,'[1]통합 판매내역'!A:A,R20,'[1]통합 판매내역'!C:C,$C$2)*B3 -> 0 | W25: =SUMIFS('[1]통합 판매내역'!G:G,'[1]통합 판매내역'!E:E,[1]회계!B10,'[1]통합 판매내역'!A:A,R20,'[1]통합 판매내역'!C:C,$C$2) -> 0
B26: 제품확정 | E26: 대변 | F26: 제품매출 | G26: =500000*SUMIFS('[1]통합 판매내역'!G:G,'[1]통합 판매내역'!E:E,B26,'[1]통합 판매내역'!A:A,D20,'[1]통합 판매내역'!C:C,$C$2) -> 0 | I26: =SUMIFS('[1]통합 판매내역'!G:G,'[1]통합 판매내역'!E:E,B26,'[1]통합 판매내역'!A:A,D20,'[1]통합 판매내역'!C:C,$C$2) -> 0 | L26: 대변 | M26: 제품매출 | N26: =500000*SUMIFS('[1]통합 판매내역'!G:G,'[1]통합 판매내역'!E:E,B26,'[1]통합 판매내역'!A:A,K20,'[1]통합 판매내역'!C:C,$C$2) -> 0 | P26: =SUMIFS('[1]통합 판매내역'!G:G,'[1]통합 판매내역'!E:E,B26,'[1]통합 판매내역'!A:A,K20,'[1]통합 판매내역'!C:C,$C$2) -> 0 | S26: 대변 | T26: 제품매출 | U26: =500000*SUMIFS('[1]통합 판매내역'!G:G,'[1]통합 판매내역'!E:E,B26,'[1]통합 판매내역'!A:A,R20,'[1]통합 판매내역'!C:C,$C$2) -> 0 | W26: =SUMIFS('[1]통합 판매내역'!G:G,'[1]통합 판매내역'!E:E,B26,'[1]통합 판매내역'!A:A,R20,'[1]통합 판매내역'!C:C,$C$2) -> 0
B27: 제품취소 | E27: 대변 | F27: 제품매출(취소) | G27: =SUMIFS('[1]통합 판매내역'!G:G,'[1]통합 판매내역'!E:E,[1]회계!B12,'[1]통합 판매내역'!A:A,D20,'[1]통합 판매내역'!C:C,$C$2)*B3 -> 0 | I27: =SUMIFS('[1]통합 판매내역'!G:G,'[1]통합 판매내역'!E:E,[1]회계!B12,'[1]통합 판매내역'!A:A,D20,'[1]통합 판매내역'!C:C,$C$2) -> 0 | L27: 대변 | M27: 제품매출(취소) | N27: =SUMIFS('[1]통합 판매내역'!G:G,'[1]통합 판매내역'!E:E,[1]회계!B12,'[1]통합 판매내역'!A:A,K20,'[1]통합 판매내역'!C:C,$C$2)*B3 -> 0 | P27: =SUMIFS('[1]통합 판매내역'!G:G,'[1]통합 판매내역'!E:E,[1]회계!B12,'[1]통합 판매내역'!A:A,K20,'[1]통합 판매내역'!C:C,$C$2) -> 0 | S27: 대변 | T27: 제품매출(취소) | U27: =SUMIFS('[1]통합 판매내역'!G:G,'[1]통합 판매내역'!E:E,[1]회계!B12,'[1]통합 판매내역'!A:A,R20,'[1]통합 판매내역'!C:C,$C$2)*B3 -> 0 | W27: =SUMIFS('[1]통합 판매내역'!G:G,'[1]통합 판매내역'!E:E,[1]회계!B12,'[1]통합 판매내역'!A:A,R20,'[1]통합 판매내역'!C:C,$C$2) -> 0
B28: 신용카드 | E28: 대변 | F28: 부가세예수금 | G28: =H28*10% -> 0 | H28: =I28/1.1 -> 0 | I28: =SUMIFS('[1]통합 판매내역'!H:H,'[1]통합 판매내역'!A:A,D20,'[1]통합 판매내역'!C:C,$C$2) -> 0 | L28: 대변 | M28: 부가세예수금 | N28: =O28*10% -> 0 | O28: =P28/1.1 -> 0 | P28: =SUMIFS('[1]통합 판매내역'!H:H,'[1]통합 판매내역'!A:A,[1]회계!K20,'[1]통합 판매내역'!C:C,$C$2) -> 0 | S28: 대변 | T28: 부가세예수금 | U28: =V28*10% -> 0 | V28: =W28/1.1 -> 0 | W28: =SUMIFS('[1]통합 판매내역'!H:H,'[1]통합 판매내역'!A:A,R20,'[1]통합 판매내역'!C:C,$C$2) -> 0
B29: 현금영수증 | E29: 대변 | F29: 부가세예수금 | G29: =H29*10% -> 0 | H29: =I29/1.1 -> 0 | I29: =SUMIFS('[1]통합 판매내역'!I:I,'[1]통합 판매내역'!A:A,D20,'[1]통합 판매내역'!C:C,$C$2) -> 0 | L29: 대변 | M29: 부가세예수금 | N29: =O29*10% -> 0 | O29: =P29/1.1 -> 0 | P29: =SUMIFS('[1]통합 판매내역'!I:I,'[1]통합 판매내역'!A:A,[1]회계!K20,'[1]통합 판매내역'!C:C,$C$2) -> 0 | S29: 대변 | T29: 부가세예수금 | U29: =V29*10% -> 0 | V29: =W29/1.1 -> 0 | W29: =SUMIFS('[1]통합 판매내역'!I:I,'[1]통합 판매내역'!A:A,R20,'[1]통합 판매내역'!C:C,$C$2) -> 0
B30: 기타 | E30: 대변 | F30: 부가세예수금 | G30: =H30*10% -> 0 | H30: =I30/1.1 -> 0 | I30: =SUMIFS('[1]통합 판매내역'!K:K,'[1]통합 판매내역'!A:A,D20,'[1]통합 판매내역'!C:C,$C$2) -> 0 | L30: 대변 | M30: 부가세예수금 | N30: =O30*10% -> 157545.45 | O30: =P30/1.1 -> 1575454.5 | P30: =SUMIFS('[1]통합 판매내역'!K:K,'[1]통합 판매내역'!A:A,[1]회계!K20,'[1]통합 판매내역'!C:C,$C$2) -> 1733000 | S30: 대변 | T30: 부가세예수금 | U30: =V30*10% -> 0 | V30: =W30/1.1 -> 0 | W30: =SUMIFS('[1]통합 판매내역'!K:K,'[1]통합 판매내역'!A:A,R20,'[1]통합 판매내역'!C:C,$C$2) -> 0
B31: 세금계산서 | E31: 대변 | F31: 부가세예수금 | G31: =H31*10% -> 0 | H31: =I31/1.1 -> 0 | I31: =SUMIFS('[1]통합 판매내역'!J:J,'[1]통합 판매내역'!A:A,D20,'[1]통합 판매내역'!C:C,$C$2) -> 0 | L31: 대변 | M31: 부가세예수금 | N31: =O31*10% -> 0 | O31: =P31/1.1 -> 0 | P31: =SUMIFS('[1]통합 판매내역'!J:J,'[1]통합 판매내역'!A:A,[1]회계!K20,'[1]통합 판매내역'!C:C,$C$2) -> 0 | S31: 대변 | T31: 부가세예수금 | U31: =V31*10% -> 0 | V31: =W31/1.1 -> 0 | W31: =SUMIFS('[1]통합 판매내역'!J:J,'[1]통합 판매내역'!A:A,R20,'[1]통합 판매내역'!C:C,$C$2) -> 0
E32: 차변 | F32: 수수료(차액) | G32: =SUMIFS(G20:G31,E20:E31,"대변")-SUMIFS(G20:G31,E20:E31,"차변") -> 0 | L32: 차변 | M32: 수수료(차액) | N32: =SUMIFS(N20:N31,L20:L31,"대변")-SUMIFS(N20:N31,L20:L31,"차변") -> 0 | S32: 차변 | T32: 수수료(차액) | U32: =SUMIFS(U20:U31,S20:S31,"대변")-SUMIFS(U20:U31,S20:S31,"차변") -> 0
B33: 500000
B34: 제품유형 | D34: 플랫폼 | E34: 차/대 | F34: 계정과목 | G34: 금액 | H34: 공금가액 | I34: 공급대가 | K34: 플랫폼 | L34: 차/대 | M34: 계정과목 | N34: 금액 | O34: 공금가액 | P34: 공급대가 | R34: 플랫폼 | S34: 차/대 | T34: 계정과목 | U34: 금액 | V34: 공금가액 | W34: 공급대가
D35: 옥션 | E35: 차변 | F35: 외상매출금 | G35: =SUM(I43:I46) -> 550000 | K35: 베네피아 | L35: 차변 | M35: 외상매출금 | N35: =SUM(P43:P46) -> 550000 | R35: 현대홈쇼핑 | S35: 차변 | T35: 외상매출금 | U35: =SUM(W43:W46) -> 624000
B36: 부가제품 | E36: 차변 | F36: 오므론 | G36: =I36/1.1 -> 0 | I36: =-SUMIFS('[1]통합 판매내역'!H:H,'[1]통합 판매내역'!E:E,[1]회계!B36,'[1]통합 판매내역'!A:A,[1]회계!D35,'[1]통합 판매내역'!C:C,$C$2)-SUMIFS('[1]통합 판매내역'!I:I,'[1]통합 판매내역'!E:E,[1]회계!B36,'[1]통합 판매내역'!A:A,[1]회계!D35,'[1]통합 판매내역'!C:C,$C$2)-SUMIFS('[1]통합 판매내역'!J:J,'[1]통합 판매내역'!E:E,[1]회계!B36,'[1]통합 판매내역'!A:A,[1]회계!D35,'[1]통합 판매내역'!C:C,$C$2)-SUMIFS('[1]통합 판매내역'!K:K,'[1]통합 판매내역'!E:E,[1]회계!B36,'[1]통합 판매내역'!A:A,[1]회계!D35,'[1]통합 판매내역'!C:C,$C$2) -> 0 | L36: 차변 | M36: 오므론 | N36: =P36/1.1 -> 0 | P36: =-SUMIFS('[1]통합 판매내역'!H:H,'[1]통합 판매내역'!E:E,[1]회계!B36,'[1]통합 판매내역'!A:A,K35,'[1]통합 판매내역'!C:C,$C$2)-SUMIFS('[1]통합 판매내역'!I:I,'[1]통합 판매내역'!E:E,[1]회계!B36,'[1]통합 판매내역'!A:A,K35,'[1]통합 판매내역'!C:C,$C$2)-SUMIFS('[1]통합 판매내역'!J:J,'[1]통합 판매내역'!E:E,[1]회계!B36,'[1]통합 판매내역'!A:A,K35,'[1]통합 판매내역'!C:C,$C$2)-SUMIFS('[1]통합 판매내역'!K:K,'[1]통합 판매내역'!E:E,[1]회계!B36,'[1]통합 판매내역'!A:A,K35,'[1]통합 판매내역'!C:C,$C$2) -> 0 | S36: 차변 | T36: 오므론 | U36: =W36/1.1 -> -67272.727 | W36: =-SUMIFS('[1]통합 판매내역'!H:H,'[1]통합 판매내역'!E:E,[1]회계!B36,'[1]통합 판매내역'!A:A,[1]회계!R35,'[1]통합 판매내역'!C:C,$C$2)-SUMIFS('[1]통합 판매내역'!I:I,'[1]통합 판매내역'!E:E,[1]회계!B36,'[1]통합 판매내역'!A:A,[1]회계!R35,'[1]통합 판매내역'!C:C,$C$2)-SUMIFS('[1]통합 판매내역'!J:J,'[1]통합 판매내역'!E:E,[1]회계!B36,'[1]통합 판매내역'!A:A,[1]회계!R35,'[1]통합 판매내역'!C:C,$C$2)-SUMIFS('[1]통합 판매내역'!K:K,'[1]통합 판매내역'!E:E,[1]회계!B36,'[1]통합 판매내역'!A:A,[1]회계!R35,'[1]통합 판매내역'!C:C,$C$2) -> -74000
B37: 배송비 | E37: 차변 | F37: 배송비 | G37: =I37/1.1 -> 0 | I37: =-SUMIFS('[1]통합 판매내역'!H:H,'[1]통합 판매내역'!E:E,[1]회계!B37,'[1]통합 판매내역'!A:A,D35,'[1]통합 판매내역'!C:C,$C$2)-SUMIFS('[1]통합 판매내역'!I:I,'[1]통합 판매내역'!E:E,[1]회계!B37,'[1]통합 판매내역'!A:A,D35,'[1]통합 판매내역'!C:C,$C$2)-SUMIFS('[1]통합 판매내역'!J:J,'[1]통합 판매내역'!E:E,[1]회계!B37,'[1]통합 판매내역'!A:A,D35,'[1]통합 판매내역'!C:C,$C$2)-SUMIFS('[1]통합 판매내역'!K:K,'[1]통합 판매내역'!E:E,[1]회계!B37,'[1]통합 판매내역'!A:A,D35,'[1]통합 판매내역'!C:C,$C$2) -> 0 | L37: 차변 | M37: 배송비 | N37: =P37/1.1 -> 0 | P37: =-SUMIFS('[1]통합 판매내역'!H:H,'[1]통합 판매내역'!E:E,[1]회계!B37,'[1]통합 판매내역'!A:A,K35,'[1]통합 판매내역'!C:C,$C$2)-SUMIFS('[1]통합 판매내역'!I:I,'[1]통합 판매내역'!E:E,[1]회계!B37,'[1]통합 판매내역'!A:A,K35,'[1]통합 판매내역'!C:C,$C$2)-SUMIFS('[1]통합 판매내역'!J:J,'[1]통합 판매내역'!E:E,[1]회계!B37,'[1]통합 판매내역'!A:A,K35,'[1]통합 판매내역'!C:C,$C$2)-SUMIFS('[1]통합 판매내역'!K:K,'[1]통합 판매내역'!E:E,[1]회계!B37,'[1]통합 판매내역'!A:A,K35,'[1]통합 판매내역'!C:C,$C$2) -> 0 | S37: 차변 | T37: 배송비 | U37: =W37/1.1 -> 0 | W37: =-SUMIFS('[1]통합 판매내역'!H:H,'[1]통합 판매내역'!E:E,[1]회계!B37,'[1]통합 판매내역'!A:A,R35,'[1]통합 판매내역'!C:C,$C$2)-SUMIFS('[1]통합 판매내역'!I:I,'[1]통합 판매내역'!E:E,[1]회계!B37,'[1]통합 판매내역'!A:A,R35,'[1]통합 판매내역'!C:C,$C$2)-SUMIFS('[1]통합 판매내역'!J:J,'[1]통합 판매내역'!E:E,[1]회계!B37,'[1]통합 판매내역'!A:A,R35,'[1]통합 판매내역'!C:C,$C$2)-SUMIFS('[1]통합 판매내역'!K:K,'[1]통합 판매내역'!E:E,[1]회계!B37,'[1]통합 판매내역'!A:A,R35,'[1]통합 판매내역'!C:C,$C$2) -> 0
B38: 제품확정 | E38: 차변 | F38: 선수금 | G38: =500000*SUMIFS('[1]통합 판매내역'!G:G,'[1]통합 판매내역'!E:E,[1]회계!B38,'[1]통합 판매내역'!A:A,[1]회계!D35,'[1]통합 판매내역'!C:C,$C$2) -> 0 | L38: 차변 | M38: 선수금 | N38: =500000*SUMIFS('[1]통합 판매내역'!G:G,'[1]통합 판매내역'!E:E,[1]회계!B38,'[1]통합 판매내역'!A:A,K35,'[1]통합 판매내역'!C:C,$C$2) -> 0 | S38: 차변 | T38: 선수금 | U38: =500000*SUMIFS('[1]통합 판매내역'!G:G,'[1]통합 판매내역'!E:E,[1]회계!B38,'[1]통합 판매내역'!A:A,[1]회계!R35,'[1]통합 판매내역'!C:C,$C$2) -> 0
B39: 사이즈미정 | E39: 차변 | F39: 선수금 | G39: =I39/1.1 -> 0 | I39: =-SUMIFS('[1]통합 판매내역'!H:H,'[1]통합 판매내역'!E:E,B39,'[1]통합 판매내역'!A:A,D35,'[1]통합 판매내역'!C:C,$C$2)-SUMIFS('[1]통합 판매내역'!I:I,'[1]통합 판매내역'!E:E,B39,'[1]통합 판매내역'!A:A,D35,'[1]통합 판매내역'!C:C,$C$2)-SUMIFS('[1]통합 판매내역'!J:J,'[1]통합 판매내역'!E:E,B39,'[1]통합 판매내역'!A:A,D35,'[1]통합 판매내역'!C:C,$C$2)-SUMIFS('[1]통합 판매내역'!K:K,'[1]통합 판매내역'!E:E,B39,'[1]통합 판매내역'!A:A,D35,'[1]통합 판매내역'!C:C,$C$2) -> 0 | L39: 차변 | M39: 선수금 | N39: =P39/1.1 -> -500000 | P39: =-SUMIFS('[1]통합 판매내역'!H:H,'[1]통합 판매내역'!E:E,B39,'[1]통합 판매내역'!A:A,K35,'[1]통합 판매내역'!C:C,$C$2)-SUMIFS('[1]통합 판매내역'!I:I,'[1]통합 판매내역'!E:E,B39,'[1]통합 판매내역'!A:A,K35,'[1]통합 판매내역'!C:C,$C$2)-SUMIFS('[1]통합 판매내역'!J:J,'[1]통합 판매내역'!E:E,B39,'[1]통합 판매내역'!A:A,K35,'[1]통합 판매내역'!C:C,$C$2)-SUMIFS('[1]통합 판매내역'!K:K,'[1]통합 판매내역'!E:E,B39,'[1]통합 판매내역'!A:A,K35,'[1]통합 판매내역'!C:C,$C$2) -> -550000 | S39: 차변 | T39: 선수금 | U39: =W39/1.1 -> 0 | W39: =-SUMIFS('[1]통합 판매내역'!H:H,'[1]통합 판매내역'!E:E,B39,'[1]통합 판매내역'!A:A,R35,'[1]통합 판매내역'!C:C,$C$2)-SUMIFS('[1]통합 판매내역'!I:I,'[1]통합 판매내역'!E:E,B39,'[1]통합 판매내역'!A:A,R35,'[1]통합 판매내역'!C:C,$C$2)-SUMIFS('[1]통합 판매내역'!J:J,'[1]통합 판매내역'!E:E,B39,'[1]통합 판매내역'!A:A,R35,'[1]통합 판매내역'!C:C,$C$2)-SUMIFS('[1]통합 판매내역'!K:K,'[1]통합 판매내역'!E:E,B39,'[1]통합 판매내역'!A:A,R35,'[1]통합 판매내역'!C:C,$C$2) -> 0
B40: 제품 | E40: 대변 | F40: 제품매출 | G40: =SUMIFS('[1]통합 판매내역'!G:G,'[1]통합 판매내역'!E:E,[1]회계!B10,'[1]통합 판매내역'!A:A,D35,'[1]통합 판매내역'!C:C,$C$2)*B3 -> 500000 | I40: =SUMIFS('[1]통합 판매내역'!G:G,'[1]통합 판매내역'!E:E,[1]회계!B10,'[1]통합 판매내역'!A:A,D35,'[1]통합 판매내역'!C:C,$C$2) -> 1 | L40: 대변 | M40: 제품매출 | N40: =SUMIFS('[1]통합 판매내역'!G:G,'[1]통합 판매내역'!E:E,[1]회계!B10,'[1]통합 판매내역'!A:A,K35,'[1]통합 판매내역'!C:C,$C$2)*B3 -> 0 | P40: =SUMIFS('[1]통합 판매내역'!G:G,'[1]통합 판매내역'!E:E,[1]회계!B10,'[1]통합 판매내역'!A:A,K35,'[1]통합 판매내역'!C:C,$C$2) -> 0 | S40: 대변 | T40: 제품매출 | U40: =SUMIFS('[1]통합 판매내역'!G:G,'[1]통합 판매내역'!E:E,[1]회계!B10,'[1]통합 판매내역'!A:A,R35,'[1]통합 판매내역'!C:C,$C$2)*B3 -> 500000 | W40: =SUMIFS('[1]통합 판매내역'!G:G,'[1]통합 판매내역'!E:E,[1]회계!B10,'[1]통합 판매내역'!A:A,R35,'[1]통합 판매내역'!C:C,$C$2) -> 1
B41: 제품확정 | E41: 대변 | F41: 제품매출 | G41: =500000*SUMIFS('[1]통합 판매내역'!G:G,'[1]통합 판매내역'!E:E,B26,'[1]통합 판매내역'!A:A,D35,'[1]통합 판매내역'!C:C,$C$2) -> 0 | I41: =SUMIFS('[1]통합 판매내역'!G:G,'[1]통합 판매내역'!E:E,B26,'[1]통합 판매내역'!A:A,D35,'[1]통합 판매내역'!C:C,$C$2) -> 0 | L41: 대변 | M41: 제품매출 | N41: =500000*SUMIFS('[1]통합 판매내역'!G:G,'[1]통합 판매내역'!E:E,B26,'[1]통합 판매내역'!A:A,K35,'[1]통합 판매내역'!C:C,$C$2) -> 0 | P41: =SUMIFS('[1]통합 판매내역'!G:G,'[1]통합 판매내역'!E:E,B26,'[1]통합 판매내역'!A:A,K35,'[1]통합 판매내역'!C:C,$C$2) -> 0 | S41: 대변 | T41: 제품매출 | U41: =500000*SUMIFS('[1]통합 판매내역'!G:G,'[1]통합 판매내역'!E:E,B26,'[1]통합 판매내역'!A:A,R35,'[1]통합 판매내역'!C:C,$C$2) -> 0 | W41: =SUMIFS('[1]통합 판매내역'!G:G,'[1]통합 판매내역'!E:E,B26,'[1]통합 판매내역'!A:A,R35,'[1]통합 판매내역'!C:C,$C$2) -> 0
...
